Creating test database for alias 'default'...
EEEEEE
======================================================================
ERROR: test_access_protected_endpoint (users.tests.AuthTests.test_access_protected_endpoint)
----------------------------------------------------------------------
Traceback (most recent call last):
  File "/home/aubrey/Projects/Django/writing-site/.env/lib/python3.13/site-packages/django/db/backends/utils.py", line 105, in _execute
    return self.cursor.execute(sql, params)
           ~~~~~~~~~~~~~~~~~~~^^^^^^^^^^^^^
  File "/home/aubrey/Projects/Django/writing-site/.env/lib/python3.13/site-packages/django/db/backends/sqlite3/base.py", line 360, in execute
    return super().execute(query, params)
           ~~~~~~~~~~~~~~~^^^^^^^^^^^^^^^
sqlite3.IntegrityError: UNIQUE constraint failed: users_profile.user_id

The above exception was the direct cause of the following exception:

Traceback (most recent call last):
  File "/home/aubrey/Projects/Django/writing-site/backend/users/tests.py", line 19, in setUp
    self.profile = Profile.objects.create(user=self.user, name='new user')
                   ~~~~~~~~~~~~~~~~~~~~~~^^^^^^^^^^^^^^^^^^^^^^^^^^^^^^^^^
  File "/home/aubrey/Projects/Django/writing-site/.env/lib/python3.13/site-packages/django/db/models/manager.py", line 87, in manager_method
    return getattr(self.get_queryset(), name)(*args, **kwargs)
           ~~~~~~~~~~~~~~~~~~~~~~~~~~~~~~~~~~^^^^^^^^^^^^^^^^^
  File "/home/aubrey/Projects/Django/writing-site/.env/lib/python3.13/site-packages/django/db/models/query.py", line 663, in create
    obj.save(force_insert=True, using=self.db)
    ~~~~~~~~^^^^^^^^^^^^^^^^^^^^^^^^^^^^^^^^^^
  File "/home/aubrey/Projects/Django/writing-site/.env/lib/python3.13/site-packages/django/db/models/base.py", line 902, in save
    self.save_base(
    ~~~~~~~~~~~~~~^
        using=using,
        ^^^^^^^^^^^^
    ...<2 lines>...
        update_fields=update_fields,
        ^^^^^^^^^^^^^^^^^^^^^^^^^^^^
    )
    ^
  File "/home/aubrey/Projects/Django/writing-site/.env/lib/python3.13/site-packages/django/db/models/base.py", line 1008, in save_base
    updated = self._save_table(
        raw,
    ...<4 lines>...
        update_fields,
    )
  File "/home/aubrey/Projects/Django/writing-site/.env/lib/python3.13/site-packages/django/db/models/base.py", line 1169, in _save_table
    results = self._do_insert(
        cls._base_manager, using, fields, returning_fields, raw
    )
  File "/home/aubrey/Projects/Django/writing-site/.env/lib/python3.13/site-packages/django/db/models/base.py", line 1210, in _do_insert
    return manager._insert(
           ~~~~~~~~~~~~~~~^
        [self],
        ^^^^^^^
    ...<3 lines>...
        raw=raw,
        ^^^^^^^^
    )
    ^
  File "/home/aubrey/Projects/Django/writing-site/.env/lib/python3.13/site-packages/django/db/models/manager.py", line 87, in manager_method
    return getattr(self.get_queryset(), name)(*args, **kwargs)
           ~~~~~~~~~~~~~~~~~~~~~~~~~~~~~~~~~~^^^^^^^^^^^^^^^^^
  File "/home/aubrey/Projects/Django/writing-site/.env/lib/python3.13/site-packages/django/db/models/query.py", line 1868, in _insert
    return query.get_compiler(using=using).execute_sql(returning_fields)
           ~~~~~~~~~~~~~~~~~~~~~~~~~~~~~~~~~~~~~~~~~~~^^^^^^^^^^^^^^^^^^
  File "/home/aubrey/Projects/Django/writing-site/.env/lib/python3.13/site-packages/django/db/models/sql/compiler.py", line 1882, in execute_sql
    cursor.execute(sql, params)
    ~~~~~~~~~~~~~~^^^^^^^^^^^^^
  File "/home/aubrey/Projects/Django/writing-site/.env/lib/python3.13/site-packages/django/db/backends/utils.py", line 79, in execute
    return self._execute_with_wrappers(
           ~~~~~~~~~~~~~~~~~~~~~~~~~~~^
        sql, params, many=False, executor=self._execute
        ^^^^^^^^^^^^^^^^^^^^^^^^^^^^^^^^^^^^^^^^^^^^^^^
    )
    ^
  File "/home/aubrey/Projects/Django/writing-site/.env/lib/python3.13/site-packages/django/db/backends/utils.py", line 92, in _execute_with_wrappers
    return executor(sql, params, many, context)
  File "/home/aubrey/Projects/Django/writing-site/.env/lib/python3.13/site-packages/django/db/backends/utils.py", line 100, in _execute
    with self.db.wrap_database_errors:
         ^^^^^^^^^^^^^^^^^^^^^^^^^^^^
  File "/home/aubrey/Projects/Django/writing-site/.env/lib/python3.13/site-packages/django/db/utils.py", line 91, in __exit__
    raise dj_exc_value.with_traceback(traceback) from exc_value
  File "/home/aubrey/Projects/Django/writing-site/.env/lib/python3.13/site-packages/django/db/backends/utils.py", line 105, in _execute
    return self.cursor.execute(sql, params)
           ~~~~~~~~~~~~~~~~~~~^^^^^^^^^^^^^
  File "/home/aubrey/Projects/Django/writing-site/.env/lib/python3.13/site-packages/django/db/backends/sqlite3/base.py", line 360, in execute
    return super().execute(query, params)
           ~~~~~~~~~~~~~~~^^^^^^^^^^^^^^^
django.db.utils.IntegrityError: UNIQUE constraint failed: users_profile.user_id

======================================================================
ERROR: test_login_invalid_credentials (users.tests.AuthTests.test_login_invalid_credentials)
----------------------------------------------------------------------
Traceback (most recent call last):
  File "/home/aubrey/Projects/Django/writing-site/.env/lib/python3.13/site-packages/django/db/backends/utils.py", line 105, in _execute
    return self.cursor.execute(sql, params)
           ~~~~~~~~~~~~~~~~~~~^^^^^^^^^^^^^
  File "/home/aubrey/Projects/Django/writing-site/.env/lib/python3.13/site-packages/django/db/backends/sqlite3/base.py", line 360, in execute
    return super().execute(query, params)
           ~~~~~~~~~~~~~~~^^^^^^^^^^^^^^^
sqlite3.IntegrityError: UNIQUE constraint failed: users_profile.user_id

The above exception was the direct cause of the following exception:

Traceback (most recent call last):
  File "/home/aubrey/Projects/Django/writing-site/backend/users/tests.py", line 19, in setUp
    self.profile = Profile.objects.create(user=self.user, name='new user')
                   ~~~~~~~~~~~~~~~~~~~~~~^^^^^^^^^^^^^^^^^^^^^^^^^^^^^^^^^
  File "/home/aubrey/Projects/Django/writing-site/.env/lib/python3.13/site-packages/django/db/models/manager.py", line 87, in manager_method
    return getattr(self.get_queryset(), name)(*args, **kwargs)
           ~~~~~~~~~~~~~~~~~~~~~~~~~~~~~~~~~~^^^^^^^^^^^^^^^^^
  File "/home/aubrey/Projects/Django/writing-site/.env/lib/python3.13/site-packages/django/db/models/query.py", line 663, in create
    obj.save(force_insert=True, using=self.db)
    ~~~~~~~~^^^^^^^^^^^^^^^^^^^^^^^^^^^^^^^^^^
  File "/home/aubrey/Projects/Django/writing-site/.env/lib/python3.13/site-packages/django/db/models/base.py", line 902, in save
    self.save_base(
    ~~~~~~~~~~~~~~^
        using=using,
        ^^^^^^^^^^^^
    ...<2 lines>...
        update_fields=update_fields,
        ^^^^^^^^^^^^^^^^^^^^^^^^^^^^
    )
    ^
  File "/home/aubrey/Projects/Django/writing-site/.env/lib/python3.13/site-packages/django/db/models/base.py", line 1008, in save_base
    updated = self._save_table(
        raw,
    ...<4 lines>...
        update_fields,
    )
  File "/home/aubrey/Projects/Django/writing-site/.env/lib/python3.13/site-packages/django/db/models/base.py", line 1169, in _save_table
    results = self._do_insert(
        cls._base_manager, using, fields, returning_fields, raw
    )
  File "/home/aubrey/Projects/Django/writing-site/.env/lib/python3.13/site-packages/django/db/models/base.py", line 1210, in _do_insert
    return manager._insert(
           ~~~~~~~~~~~~~~~^
        [self],
        ^^^^^^^
    ...<3 lines>...
        raw=raw,
        ^^^^^^^^
    )
    ^
  File "/home/aubrey/Projects/Django/writing-site/.env/lib/python3.13/site-packages/django/db/models/manager.py", line 87, in manager_method
    return getattr(self.get_queryset(), name)(*args, **kwargs)
           ~~~~~~~~~~~~~~~~~~~~~~~~~~~~~~~~~~^^^^^^^^^^^^^^^^^
  File "/home/aubrey/Projects/Django/writing-site/.env/lib/python3.13/site-packages/django/db/models/query.py", line 1868, in _insert
    return query.get_compiler(using=using).execute_sql(returning_fields)
           ~~~~~~~~~~~~~~~~~~~~~~~~~~~~~~~~~~~~~~~~~~~^^^^^^^^^^^^^^^^^^
  File "/home/aubrey/Projects/Django/writing-site/.env/lib/python3.13/site-packages/django/db/models/sql/compiler.py", line 1882, in execute_sql
    cursor.execute(sql, params)
    ~~~~~~~~~~~~~~^^^^^^^^^^^^^
  File "/home/aubrey/Projects/Django/writing-site/.env/lib/python3.13/site-packages/django/db/backends/utils.py", line 79, in execute
    return self._execute_with_wrappers(
           ~~~~~~~~~~~~~~~~~~~~~~~~~~~^
        sql, params, many=False, executor=self._execute
        ^^^^^^^^^^^^^^^^^^^^^^^^^^^^^^^^^^^^^^^^^^^^^^^
    )
    ^
  File "/home/aubrey/Projects/Django/writing-site/.env/lib/python3.13/site-packages/django/db/backends/utils.py", line 92, in _execute_with_wrappers
    return executor(sql, params, many, context)
  File "/home/aubrey/Projects/Django/writing-site/.env/lib/python3.13/site-packages/django/db/backends/utils.py", line 100, in _execute
    with self.db.wrap_database_errors:
         ^^^^^^^^^^^^^^^^^^^^^^^^^^^^
  File "/home/aubrey/Projects/Django/writing-site/.env/lib/python3.13/site-packages/django/db/utils.py", line 91, in __exit__
    raise dj_exc_value.with_traceback(traceback) from exc_value
  File "/home/aubrey/Projects/Django/writing-site/.env/lib/python3.13/site-packages/django/db/backends/utils.py", line 105, in _execute
    return self.cursor.execute(sql, params)
           ~~~~~~~~~~~~~~~~~~~^^^^^^^^^^^^^
  File "/home/aubrey/Projects/Django/writing-site/.env/lib/python3.13/site-packages/django/db/backends/sqlite3/base.py", line 360, in execute
    return super().execute(query, params)
           ~~~~~~~~~~~~~~~^^^^^^^^^^^^^^^
django.db.utils.IntegrityError: UNIQUE constraint failed: users_profile.user_id

======================================================================
ERROR: test_login_success (users.tests.AuthTests.test_login_success)
----------------------------------------------------------------------
Traceback (most recent call last):
  File "/home/aubrey/Projects/Django/writing-site/.env/lib/python3.13/site-packages/django/db/backends/utils.py", line 105, in _execute
    return self.cursor.execute(sql, params)
           ~~~~~~~~~~~~~~~~~~~^^^^^^^^^^^^^
  File "/home/aubrey/Projects/Django/writing-site/.env/lib/python3.13/site-packages/django/db/backends/sqlite3/base.py", line 360, in execute
    return super().execute(query, params)
           ~~~~~~~~~~~~~~~^^^^^^^^^^^^^^^
sqlite3.IntegrityError: UNIQUE constraint failed: users_profile.user_id

The above exception was the direct cause of the following exception:

Traceback (most recent call last):
  File "/home/aubrey/Projects/Django/writing-site/backend/users/tests.py", line 19, in setUp
    self.profile = Profile.objects.create(user=self.user, name='new user')
                   ~~~~~~~~~~~~~~~~~~~~~~^^^^^^^^^^^^^^^^^^^^^^^^^^^^^^^^^
  File "/home/aubrey/Projects/Django/writing-site/.env/lib/python3.13/site-packages/django/db/models/manager.py", line 87, in manager_method
    return getattr(self.get_queryset(), name)(*args, **kwargs)
           ~~~~~~~~~~~~~~~~~~~~~~~~~~~~~~~~~~^^^^^^^^^^^^^^^^^
  File "/home/aubrey/Projects/Django/writing-site/.env/lib/python3.13/site-packages/django/db/models/query.py", line 663, in create
    obj.save(force_insert=True, using=self.db)
    ~~~~~~~~^^^^^^^^^^^^^^^^^^^^^^^^^^^^^^^^^^
  File "/home/aubrey/Projects/Django/writing-site/.env/lib/python3.13/site-packages/django/db/models/base.py", line 902, in save
    self.save_base(
    ~~~~~~~~~~~~~~^
        using=using,
        ^^^^^^^^^^^^
    ...<2 lines>...
        update_fields=update_fields,
        ^^^^^^^^^^^^^^^^^^^^^^^^^^^^
    )
    ^
  File "/home/aubrey/Projects/Django/writing-site/.env/lib/python3.13/site-packages/django/db/models/base.py", line 1008, in save_base
    updated = self._save_table(
        raw,
    ...<4 lines>...
        update_fields,
    )
  File "/home/aubrey/Projects/Django/writing-site/.env/lib/python3.13/site-packages/django/db/models/base.py", line 1169, in _save_table
    results = self._do_insert(
        cls._base_manager, using, fields, returning_fields, raw
    )
  File "/home/aubrey/Projects/Django/writing-site/.env/lib/python3.13/site-packages/django/db/models/base.py", line 1210, in _do_insert
    return manager._insert(
           ~~~~~~~~~~~~~~~^
        [self],
        ^^^^^^^
    ...<3 lines>...
        raw=raw,
        ^^^^^^^^
    )
    ^
  File "/home/aubrey/Projects/Django/writing-site/.env/lib/python3.13/site-packages/django/db/models/manager.py", line 87, in manager_method
    return getattr(self.get_queryset(), name)(*args, **kwargs)
           ~~~~~~~~~~~~~~~~~~~~~~~~~~~~~~~~~~^^^^^^^^^^^^^^^^^
  File "/home/aubrey/Projects/Django/writing-site/.env/lib/python3.13/site-packages/django/db/models/query.py", line 1868, in _insert
    return query.get_compiler(using=using).execute_sql(returning_fields)
           ~~~~~~~~~~~~~~~~~~~~~~~~~~~~~~~~~~~~~~~~~~~^^^^^^^^^^^^^^^^^^
  File "/home/aubrey/Projects/Django/writing-site/.env/lib/python3.13/site-packages/django/db/models/sql/compiler.py", line 1882, in execute_sql
    cursor.execute(sql, params)
    ~~~~~~~~~~~~~~^^^^^^^^^^^^^
  File "/home/aubrey/Projects/Django/writing-site/.env/lib/python3.13/site-packages/django/db/backends/utils.py", line 79, in execute
    return self._execute_with_wrappers(
           ~~~~~~~~~~~~~~~~~~~~~~~~~~~^
        sql, params, many=False, executor=self._execute
        ^^^^^^^^^^^^^^^^^^^^^^^^^^^^^^^^^^^^^^^^^^^^^^^
    )
    ^
  File "/home/aubrey/Projects/Django/writing-site/.env/lib/python3.13/site-packages/django/db/backends/utils.py", line 92, in _execute_with_wrappers
    return executor(sql, params, many, context)
  File "/home/aubrey/Projects/Django/writing-site/.env/lib/python3.13/site-packages/django/db/backends/utils.py", line 100, in _execute
    with self.db.wrap_database_errors:
         ^^^^^^^^^^^^^^^^^^^^^^^^^^^^
  File "/home/aubrey/Projects/Django/writing-site/.env/lib/python3.13/site-packages/django/db/utils.py", line 91, in __exit__
    raise dj_exc_value.with_traceback(traceback) from exc_value
  File "/home/aubrey/Projects/Django/writing-site/.env/lib/python3.13/site-packages/django/db/backends/utils.py", line 105, in _execute
    return self.cursor.execute(sql, params)
           ~~~~~~~~~~~~~~~~~~~^^^^^^^^^^^^^
  File "/home/aubrey/Projects/Django/writing-site/.env/lib/python3.13/site-packages/django/db/backends/sqlite3/base.py", line 360, in execute
    return super().execute(query, params)
           ~~~~~~~~~~~~~~~^^^^^^^^^^^^^^^
django.db.utils.IntegrityError: UNIQUE constraint failed: users_profile.user_id

======================================================================
ERROR: test_profile_auto_creation_signal (users.tests.AuthTests.test_profile_auto_creation_signal)
----------------------------------------------------------------------
Traceback (most recent call last):
  File "/home/aubrey/Projects/Django/writing-site/.env/lib/python3.13/site-packages/django/db/backends/utils.py", line 105, in _execute
    return self.cursor.execute(sql, params)
           ~~~~~~~~~~~~~~~~~~~^^^^^^^^^^^^^
  File "/home/aubrey/Projects/Django/writing-site/.env/lib/python3.13/site-packages/django/db/backends/sqlite3/base.py", line 360, in execute
    return super().execute(query, params)
           ~~~~~~~~~~~~~~~^^^^^^^^^^^^^^^
sqlite3.IntegrityError: UNIQUE constraint failed: users_profile.user_id

The above exception was the direct cause of the following exception:

Traceback (most recent call last):
  File "/home/aubrey/Projects/Django/writing-site/backend/users/tests.py", line 19, in setUp
    self.profile = Profile.objects.create(user=self.user, name='new user')
                   ~~~~~~~~~~~~~~~~~~~~~~^^^^^^^^^^^^^^^^^^^^^^^^^^^^^^^^^
  File "/home/aubrey/Projects/Django/writing-site/.env/lib/python3.13/site-packages/django/db/models/manager.py", line 87, in manager_method
    return getattr(self.get_queryset(), name)(*args, **kwargs)
           ~~~~~~~~~~~~~~~~~~~~~~~~~~~~~~~~~~^^^^^^^^^^^^^^^^^
  File "/home/aubrey/Projects/Django/writing-site/.env/lib/python3.13/site-packages/django/db/models/query.py", line 663, in create
    obj.save(force_insert=True, using=self.db)
    ~~~~~~~~^^^^^^^^^^^^^^^^^^^^^^^^^^^^^^^^^^
  File "/home/aubrey/Projects/Django/writing-site/.env/lib/python3.13/site-packages/django/db/models/base.py", line 902, in save
    self.save_base(
    ~~~~~~~~~~~~~~^
        using=using,
        ^^^^^^^^^^^^
    ...<2 lines>...
        update_fields=update_fields,
        ^^^^^^^^^^^^^^^^^^^^^^^^^^^^
    )
    ^
  File "/home/aubrey/Projects/Django/writing-site/.env/lib/python3.13/site-packages/django/db/models/base.py", line 1008, in save_base
    updated = self._save_table(
        raw,
    ...<4 lines>...
        update_fields,
    )
  File "/home/aubrey/Projects/Django/writing-site/.env/lib/python3.13/site-packages/django/db/models/base.py", line 1169, in _save_table
    results = self._do_insert(
        cls._base_manager, using, fields, returning_fields, raw
    )
  File "/home/aubrey/Projects/Django/writing-site/.env/lib/python3.13/site-packages/django/db/models/base.py", line 1210, in _do_insert
    return manager._insert(
           ~~~~~~~~~~~~~~~^
        [self],
        ^^^^^^^
    ...<3 lines>...
        raw=raw,
        ^^^^^^^^
    )
    ^
  File "/home/aubrey/Projects/Django/writing-site/.env/lib/python3.13/site-packages/django/db/models/manager.py", line 87, in manager_method
    return getattr(self.get_queryset(), name)(*args, **kwargs)
           ~~~~~~~~~~~~~~~~~~~~~~~~~~~~~~~~~~^^^^^^^^^^^^^^^^^
  File "/home/aubrey/Projects/Django/writing-site/.env/lib/python3.13/site-packages/django/db/models/query.py", line 1868, in _insert
    return query.get_compiler(using=using).execute_sql(returning_fields)
           ~~~~~~~~~~~~~~~~~~~~~~~~~~~~~~~~~~~~~~~~~~~^^^^^^^^^^^^^^^^^^
  File "/home/aubrey/Projects/Django/writing-site/.env/lib/python3.13/site-packages/django/db/models/sql/compiler.py", line 1882, in execute_sql
    cursor.execute(sql, params)
    ~~~~~~~~~~~~~~^^^^^^^^^^^^^
  File "/home/aubrey/Projects/Django/writing-site/.env/lib/python3.13/site-packages/django/db/backends/utils.py", line 79, in execute
    return self._execute_with_wrappers(
           ~~~~~~~~~~~~~~~~~~~~~~~~~~~^
        sql, params, many=False, executor=self._execute
        ^^^^^^^^^^^^^^^^^^^^^^^^^^^^^^^^^^^^^^^^^^^^^^^
    )
    ^
  File "/home/aubrey/Projects/Django/writing-site/.env/lib/python3.13/site-packages/django/db/backends/utils.py", line 92, in _execute_with_wrappers
    return executor(sql, params, many, context)
  File "/home/aubrey/Projects/Django/writing-site/.env/lib/python3.13/site-packages/django/db/backends/utils.py", line 100, in _execute
    with self.db.wrap_database_errors:
         ^^^^^^^^^^^^^^^^^^^^^^^^^^^^
  File "/home/aubrey/Projects/Django/writing-site/.env/lib/python3.13/site-packages/django/db/utils.py", line 91, in __exit__
    raise dj_exc_value.with_traceback(traceback) from exc_value
  File "/home/aubrey/Projects/Django/writing-site/.env/lib/python3.13/site-packages/django/db/backends/utils.py", line 105, in _execute
    return self.cursor.execute(sql, params)
           ~~~~~~~~~~~~~~~~~~~^^^^^^^^^^^^^
  File "/home/aubrey/Projects/Django/writing-site/.env/lib/python3.13/site-packages/django/db/backends/sqlite3/base.py", line 360, in execute
    return super().execute(query, params)
           ~~~~~~~~~~~~~~~^^^^^^^^^^^^^^^
django.db.utils.IntegrityError: UNIQUE constraint failed: users_profile.user_id

======================================================================
ERROR: test_profile_update (users.tests.AuthTests.test_profile_update)
----------------------------------------------------------------------
Traceback (most recent call last):
  File "/home/aubrey/Projects/Django/writing-site/.env/lib/python3.13/site-packages/django/db/backends/utils.py", line 105, in _execute
    return self.cursor.execute(sql, params)
           ~~~~~~~~~~~~~~~~~~~^^^^^^^^^^^^^
  File "/home/aubrey/Projects/Django/writing-site/.env/lib/python3.13/site-packages/django/db/backends/sqlite3/base.py", line 360, in execute
    return super().execute(query, params)
           ~~~~~~~~~~~~~~~^^^^^^^^^^^^^^^
sqlite3.IntegrityError: UNIQUE constraint failed: users_profile.user_id

The above exception was the direct cause of the following exception:

Traceback (most recent call last):
  File "/home/aubrey/Projects/Django/writing-site/backend/users/tests.py", line 19, in setUp
    self.profile = Profile.objects.create(user=self.user, name='new user')
                   ~~~~~~~~~~~~~~~~~~~~~~^^^^^^^^^^^^^^^^^^^^^^^^^^^^^^^^^
  File "/home/aubrey/Projects/Django/writing-site/.env/lib/python3.13/site-packages/django/db/models/manager.py", line 87, in manager_method
    return getattr(self.get_queryset(), name)(*args, **kwargs)
           ~~~~~~~~~~~~~~~~~~~~~~~~~~~~~~~~~~^^^^^^^^^^^^^^^^^
  File "/home/aubrey/Projects/Django/writing-site/.env/lib/python3.13/site-packages/django/db/models/query.py", line 663, in create
    obj.save(force_insert=True, using=self.db)
    ~~~~~~~~^^^^^^^^^^^^^^^^^^^^^^^^^^^^^^^^^^
  File "/home/aubrey/Projects/Django/writing-site/.env/lib/python3.13/site-packages/django/db/models/base.py", line 902, in save
    self.save_base(
    ~~~~~~~~~~~~~~^
        using=using,
        ^^^^^^^^^^^^
    ...<2 lines>...
        update_fields=update_fields,
        ^^^^^^^^^^^^^^^^^^^^^^^^^^^^
    )
    ^
  File "/home/aubrey/Projects/Django/writing-site/.env/lib/python3.13/site-packages/django/db/models/base.py", line 1008, in save_base
    updated = self._save_table(
        raw,
    ...<4 lines>...
        update_fields,
    )
  File "/home/aubrey/Projects/Django/writing-site/.env/lib/python3.13/site-packages/django/db/models/base.py", line 1169, in _save_table
    results = self._do_insert(
        cls._base_manager, using, fields, returning_fields, raw
    )
  File "/home/aubrey/Projects/Django/writing-site/.env/lib/python3.13/site-packages/django/db/models/base.py", line 1210, in _do_insert
    return manager._insert(
           ~~~~~~~~~~~~~~~^
        [self],
        ^^^^^^^
    ...<3 lines>...
        raw=raw,
        ^^^^^^^^
    )
    ^
  File "/home/aubrey/Projects/Django/writing-site/.env/lib/python3.13/site-packages/django/db/models/manager.py", line 87, in manager_method
    return getattr(self.get_queryset(), name)(*args, **kwargs)
           ~~~~~~~~~~~~~~~~~~~~~~~~~~~~~~~~~~^^^^^^^^^^^^^^^^^
  File "/home/aubrey/Projects/Django/writing-site/.env/lib/python3.13/site-packages/django/db/models/query.py", line 1868, in _insert
    return query.get_compiler(using=using).execute_sql(returning_fields)
           ~~~~~~~~~~~~~~~~~~~~~~~~~~~~~~~~~~~~~~~~~~~^^^^^^^^^^^^^^^^^^
  File "/home/aubrey/Projects/Django/writing-site/.env/lib/python3.13/site-packages/django/db/models/sql/compiler.py", line 1882, in execute_sql
    cursor.execute(sql, params)
    ~~~~~~~~~~~~~~^^^^^^^^^^^^^
  File "/home/aubrey/Projects/Django/writing-site/.env/lib/python3.13/site-packages/django/db/backends/utils.py", line 79, in execute
    return self._execute_with_wrappers(
           ~~~~~~~~~~~~~~~~~~~~~~~~~~~^
        sql, params, many=False, executor=self._execute
        ^^^^^^^^^^^^^^^^^^^^^^^^^^^^^^^^^^^^^^^^^^^^^^^
    )
    ^
  File "/home/aubrey/Projects/Django/writing-site/.env/lib/python3.13/site-packages/django/db/backends/utils.py", line 92, in _execute_with_wrappers
    return executor(sql, params, many, context)
  File "/home/aubrey/Projects/Django/writing-site/.env/lib/python3.13/site-packages/django/db/backends/utils.py", line 100, in _execute
    with self.db.wrap_database_errors:
         ^^^^^^^^^^^^^^^^^^^^^^^^^^^^
  File "/home/aubrey/Projects/Django/writing-site/.env/lib/python3.13/site-packages/django/db/utils.py", line 91, in __exit__
    raise dj_exc_value.with_traceback(traceback) from exc_value
  File "/home/aubrey/Projects/Django/writing-site/.env/lib/python3.13/site-packages/django/db/backends/utils.py", line 105, in _execute
    return self.cursor.execute(sql, params)
           ~~~~~~~~~~~~~~~~~~~^^^^^^^^^^^^^
  File "/home/aubrey/Projects/Django/writing-site/.env/lib/python3.13/site-packages/django/db/backends/sqlite3/base.py", line 360, in execute
    return super().execute(query, params)
           ~~~~~~~~~~~~~~~^^^^^^^^^^^^^^^
django.db.utils.IntegrityError: UNIQUE constraint failed: users_profile.user_id

======================================================================
ERROR: test_user_registration (users.tests.AuthTests.test_user_registration)
----------------------------------------------------------------------
Traceback (most recent call last):
  File "/home/aubrey/Projects/Django/writing-site/.env/lib/python3.13/site-packages/django/db/backends/utils.py", line 105, in _execute
    return self.cursor.execute(sql, params)
           ~~~~~~~~~~~~~~~~~~~^^^^^^^^^^^^^
  File "/home/aubrey/Projects/Django/writing-site/.env/lib/python3.13/site-packages/django/db/backends/sqlite3/base.py", line 360, in execute
    return super().execute(query, params)
           ~~~~~~~~~~~~~~~^^^^^^^^^^^^^^^
sqlite3.IntegrityError: UNIQUE constraint failed: users_profile.user_id

The above exception was the direct cause of the following exception:

Traceback (most recent call last):
  File "/home/aubrey/Projects/Django/writing-site/backend/users/tests.py", line 19, in setUp
    self.profile = Profile.objects.create(user=self.user, name='new user')
                   ~~~~~~~~~~~~~~~~~~~~~~^^^^^^^^^^^^^^^^^^^^^^^^^^^^^^^^^
  File "/home/aubrey/Projects/Django/writing-site/.env/lib/python3.13/site-packages/django/db/models/manager.py", line 87, in manager_method
    return getattr(self.get_queryset(), name)(*args, **kwargs)
           ~~~~~~~~~~~~~~~~~~~~~~~~~~~~~~~~~~^^^^^^^^^^^^^^^^^
  File "/home/aubrey/Projects/Django/writing-site/.env/lib/python3.13/site-packages/django/db/models/query.py", line 663, in create
    obj.save(force_insert=True, using=self.db)
    ~~~~~~~~^^^^^^^^^^^^^^^^^^^^^^^^^^^^^^^^^^
  File "/home/aubrey/Projects/Django/writing-site/.env/lib/python3.13/site-packages/django/db/models/base.py", line 902, in save
    self.save_base(
    ~~~~~~~~~~~~~~^
        using=using,
        ^^^^^^^^^^^^
    ...<2 lines>...
        update_fields=update_fields,
        ^^^^^^^^^^^^^^^^^^^^^^^^^^^^
    )
    ^
  File "/home/aubrey/Projects/Django/writing-site/.env/lib/python3.13/site-packages/django/db/models/base.py", line 1008, in save_base
    updated = self._save_table(
        raw,
    ...<4 lines>...
        update_fields,
    )
  File "/home/aubrey/Projects/Django/writing-site/.env/lib/python3.13/site-packages/django/db/models/base.py", line 1169, in _save_table
    results = self._do_insert(
        cls._base_manager, using, fields, returning_fields, raw
    )
  File "/home/aubrey/Projects/Django/writing-site/.env/lib/python3.13/site-packages/django/db/models/base.py", line 1210, in _do_insert
    return manager._insert(
           ~~~~~~~~~~~~~~~^
        [self],
        ^^^^^^^
    ...<3 lines>...
        raw=raw,
        ^^^^^^^^
    )
    ^
  File "/home/aubrey/Projects/Django/writing-site/.env/lib/python3.13/site-packages/django/db/models/manager.py", line 87, in manager_method
    return getattr(self.get_queryset(), name)(*args, **kwargs)
           ~~~~~~~~~~~~~~~~~~~~~~~~~~~~~~~~~~^^^^^^^^^^^^^^^^^
  File "/home/aubrey/Projects/Django/writing-site/.env/lib/python3.13/site-packages/django/db/models/query.py", line 1868, in _insert
    return query.get_compiler(using=using).execute_sql(returning_fields)
           ~~~~~~~~~~~~~~~~~~~~~~~~~~~~~~~~~~~~~~~~~~~^^^^^^^^^^^^^^^^^^
  File "/home/aubrey/Projects/Django/writing-site/.env/lib/python3.13/site-packages/django/db/models/sql/compiler.py", line 1882, in execute_sql
    cursor.execute(sql, params)
    ~~~~~~~~~~~~~~^^^^^^^^^^^^^
  File "/home/aubrey/Projects/Django/writing-site/.env/lib/python3.13/site-packages/django/db/backends/utils.py", line 79, in execute
    return self._execute_with_wrappers(
           ~~~~~~~~~~~~~~~~~~~~~~~~~~~^
        sql, params, many=False, executor=self._execute
        ^^^^^^^^^^^^^^^^^^^^^^^^^^^^^^^^^^^^^^^^^^^^^^^
    )
    ^
  File "/home/aubrey/Projects/Django/writing-site/.env/lib/python3.13/site-packages/django/db/backends/utils.py", line 92, in _execute_with_wrappers
    return executor(sql, params, many, context)
  File "/home/aubrey/Projects/Django/writing-site/.env/lib/python3.13/site-packages/django/db/backends/utils.py", line 100, in _execute
    with self.db.wrap_database_errors:
         ^^^^^^^^^^^^^^^^^^^^^^^^^^^^
  File "/home/aubrey/Projects/Django/writing-site/.env/lib/python3.13/site-packages/django/db/utils.py", line 91, in __exit__
    raise dj_exc_value.with_traceback(traceback) from exc_value
  File "/home/aubrey/Projects/Django/writing-site/.env/lib/python3.13/site-packages/django/db/backends/utils.py", line 105, in _execute
    return self.cursor.execute(sql, params)
           ~~~~~~~~~~~~~~~~~~~^^^^^^^^^^^^^
  File "/home/aubrey/Projects/Django/writing-site/.env/lib/python3.13/site-packages/django/db/backends/sqlite3/base.py", line 360, in execute
    return super().execute(query, params)
           ~~~~~~~~~~~~~~~^^^^^^^^^^^^^^^
django.db.utils.IntegrityError: UNIQUE constraint failed: users_profile.user_id

----------------------------------------------------------------------
Ran 6 tests in 5.893s

FAILED (errors=6)
Destroying test database for alias 'default'...
